[2025-02-26T20:46:28.858+0000] {taskinstance.py:1159} INFO - Dependencies all met for dep_context=non-requeueable deps ti=<TaskInstance: yfinance_ingestion_dag.run_mapreduce scheduled__2025-01-16T00:00:00+00:00 [queued]>
[2025-02-26T20:46:28.875+0000] {taskinstance.py:1159} INFO - Dependencies all met for dep_context=requeueable deps ti=<TaskInstance: yfinance_ingestion_dag.run_mapreduce scheduled__2025-01-16T00:00:00+00:00 [queued]>
[2025-02-26T20:46:28.876+0000] {taskinstance.py:1361} INFO - Starting attempt 2 of 2
[2025-02-26T20:46:28.985+0000] {taskinstance.py:1382} INFO - Executing <Task(BashOperator): run_mapreduce> on 2025-01-16 00:00:00+00:00
[2025-02-26T20:46:28.997+0000] {standard_task_runner.py:57} INFO - Started process 2880 to run task
[2025-02-26T20:46:29.006+0000] {standard_task_runner.py:84} INFO - Running: ['***', 'tasks', 'run', 'yfinance_ingestion_dag', 'run_mapreduce', 'scheduled__2025-01-16T00:00:00+00:00', '--job-id', '403', '--raw', '--subdir', 'DAGS_FOLDER/pipeline.py', '--cfg-path', '/tmp/tmpqlhc298h']
[2025-02-26T20:46:29.014+0000] {standard_task_runner.py:85} INFO - Job 403: Subtask run_mapreduce
[2025-02-26T20:46:29.154+0000] {task_command.py:415} INFO - Running <TaskInstance: yfinance_ingestion_dag.run_mapreduce scheduled__2025-01-16T00:00:00+00:00 [running]> on host 3c0faf52b292
[2025-02-26T20:46:29.429+0000] {taskinstance.py:1660} INFO - Exporting env vars: AIRFLOW_CTX_DAG_OWNER='etudiant' AIRFLOW_CTX_DAG_ID='yfinance_ingestion_dag' AIRFLOW_CTX_TASK_ID='run_mapreduce' AIRFLOW_CTX_EXECUTION_DATE='2025-01-16T00:00:00+00:00' AIRFLOW_CTX_TRY_NUMBER='2' AIRFLOW_CTX_DAG_RUN_ID='scheduled__2025-01-16T00:00:00+00:00'
[2025-02-26T20:46:29.434+0000] {subprocess.py:63} INFO - Tmp dir root location: /tmp
[2025-02-26T20:46:29.436+0000] {subprocess.py:75} INFO - Running command: ['/bin/bash', '-c', '\n        docker exec -i -u root namenode bash -c \'         cd /tmp &&         cp /mnt/hadoop_data/mapreduce/mapper.py . &&         cp /mnt/hadoop_data/mapreduce/reducer.py . &&         chmod +x mapper.py reducer.py &&         hdfs dfs -rm -r hdfs:///user/etudiant/crypto/processed/YYYY=2025/MM=01/DD=16 || true &&         hadoop jar /opt/hadoop-3.2.1/share/hadoop/tools/lib/hadoop-streaming-3.2.1.jar         -files mapper.py,reducer.py         -mapper "python mapper.py"         -reducer "python reducer.py"         -input hdfs:///user/etudiant/crypto/raw/YYYY=2025/MM=01/DD=16/yfinance_raw.json         -output hdfs:///user/etudiant/crypto/processed/YYYY=2025/MM=01/DD=16\'\n        ']
[2025-02-26T20:46:29.528+0000] {subprocess.py:86} INFO - Output:
[2025-02-26T20:46:34.119+0000] {subprocess.py:93} INFO - rm: `hdfs:///user/etudiant/crypto/processed/YYYY=2025/MM=01/DD=16': No such file or directory
[2025-02-26T20:46:45.043+0000] {subprocess.py:93} INFO - 2025-02-26 20:46:45,034 INFO impl.MetricsConfig: Loaded properties from hadoop-metrics2.properties
[2025-02-26T20:46:45.456+0000] {subprocess.py:93} INFO - 2025-02-26 20:46:45,450 INFO impl.MetricsSystemImpl: Scheduled Metric snapshot period at 10 second(s).
[2025-02-26T20:46:45.457+0000] {subprocess.py:93} INFO - 2025-02-26 20:46:45,450 INFO impl.MetricsSystemImpl: JobTracker metrics system started
[2025-02-26T20:46:45.646+0000] {subprocess.py:93} INFO - 2025-02-26 20:46:45,634 WARN impl.MetricsSystemImpl: JobTracker metrics system already initialized!
[2025-02-26T20:46:47.604+0000] {subprocess.py:93} INFO - 2025-02-26 20:46:47,602 INFO mapreduce.JobSubmitter: Cleaning up the staging area file:/tmp/hadoop/mapred/staging/root1976620097/.staging/job_local1976620097_0001
[2025-02-26T20:46:47.609+0000] {subprocess.py:93} INFO - 2025-02-26 20:46:47,607 ERROR streaming.StreamJob: Error Launching job : Input path does not exist: hdfs:/user/etudiant/crypto/raw/YYYY=2025/MM=01/DD=16/yfinance_raw.json
[2025-02-26T20:46:47.610+0000] {subprocess.py:93} INFO - Streaming Command Failed!
[2025-02-26T20:46:48.347+0000] {subprocess.py:97} INFO - Command exited with return code 5
[2025-02-26T20:46:48.385+0000] {taskinstance.py:1943} ERROR - Task failed with exception
Traceback (most recent call last):
  File "/home/airflow/.local/lib/python3.8/site-packages/airflow/operators/bash.py", line 210, in execute
    raise AirflowException(
airflow.exceptions.AirflowException: Bash command failed. The command returned a non-zero exit code 5.
[2025-02-26T20:46:48.416+0000] {taskinstance.py:1400} INFO - Marking task as FAILED. dag_id=yfinance_ingestion_dag, task_id=run_mapreduce, execution_date=20250116T000000, start_date=20250226T204628, end_date=20250226T204648
[2025-02-26T20:46:48.494+0000] {standard_task_runner.py:104} ERROR - Failed to execute job 403 for task run_mapreduce (Bash command failed. The command returned a non-zero exit code 5.; 2880)
[2025-02-26T20:46:48.533+0000] {local_task_job_runner.py:228} INFO - Task exited with return code 1
[2025-02-26T20:46:48.568+0000] {taskinstance.py:2784} INFO - 0 downstream tasks scheduled from follow-on schedule check
