[2025-02-25T16:58:07.948+0000] {taskinstance.py:1159} INFO - Dependencies all met for dep_context=non-requeueable deps ti=<TaskInstance: coingecko_mapreduce_dag.run_mapreduce_job manual__2025-02-25T16:52:51.701457+00:00 [queued]>
[2025-02-25T16:58:07.958+0000] {taskinstance.py:1159} INFO - Dependencies all met for dep_context=requeueable deps ti=<TaskInstance: coingecko_mapreduce_dag.run_mapreduce_job manual__2025-02-25T16:52:51.701457+00:00 [queued]>
[2025-02-25T16:58:07.959+0000] {taskinstance.py:1361} INFO - Starting attempt 2 of 2
[2025-02-25T16:58:07.974+0000] {taskinstance.py:1382} INFO - Executing <Task(PythonOperator): run_mapreduce_job> on 2025-02-25 16:52:51.701457+00:00
[2025-02-25T16:58:07.980+0000] {standard_task_runner.py:57} INFO - Started process 512 to run task
[2025-02-25T16:58:07.983+0000] {standard_task_runner.py:84} INFO - Running: ['***', 'tasks', 'run', 'coingecko_mapreduce_dag', 'run_mapreduce_job', 'manual__2025-02-25T16:52:51.701457+00:00', '--job-id', '203', '--raw', '--subdir', 'DAGS_FOLDER/test_hello.py', '--cfg-path', '/tmp/tmp_hksuob7']
[2025-02-25T16:58:07.986+0000] {standard_task_runner.py:85} INFO - Job 203: Subtask run_mapreduce_job
[2025-02-25T16:58:08.040+0000] {task_command.py:415} INFO - Running <TaskInstance: coingecko_mapreduce_dag.run_mapreduce_job manual__2025-02-25T16:52:51.701457+00:00 [running]> on host 1aa31530ca49
[2025-02-25T16:58:08.148+0000] {taskinstance.py:1660} INFO - Exporting env vars: AIRFLOW_CTX_DAG_OWNER='etudiant' AIRFLOW_CTX_DAG_ID='coingecko_mapreduce_dag' AIRFLOW_CTX_TASK_ID='run_mapreduce_job' AIRFLOW_CTX_EXECUTION_DATE='2025-02-25T16:52:51.701457+00:00' AIRFLOW_CTX_TRY_NUMBER='2' AIRFLOW_CTX_DAG_RUN_ID='manual__2025-02-25T16:52:51.701457+00:00'
[2025-02-25T16:58:18.354+0000] {taskinstance.py:1943} ERROR - Task failed with exception
Traceback (most recent call last):
  File "/home/airflow/.local/lib/python3.8/site-packages/airflow/operators/python.py", line 192, in execute
    return_value = self.execute_callable()
  File "/home/airflow/.local/lib/python3.8/site-packages/airflow/operators/python.py", line 209, in execute_callable
    return self.python_callable(*self.op_args, **self.op_kwargs)
  File "/opt/airflow/dags/test_hello.py", line 56, in run_mapreduce_job
    subprocess.run(command, check=True)
  File "/usr/local/lib/python3.8/subprocess.py", line 516, in run
    raise CalledProcessError(retcode, process.args,
subprocess.CalledProcessError: Command '['docker', 'exec', 'namenode', 'hadoop', 'jar', '/opt/hadoop-3.2.1/share/hadoop/tools/lib/hadoop-streaming-3.2.1.jar', '-input', '/user/etudiant/crypto/raw/YYYY=2025/MM=02/DD=25/coingecko_raw.json', '-output', '/user/etudiant/crypto/output/YYYY=2025/MM=02/DD=25', '-mapper', 'python3 mapper.py', '-reducer', 'python3 reducer.py', '-file', '/user/etudiant/crypto/scripts/mapper.py', '-file', '/user/etudiant/crypto/scripts/reducer.py']' returned non-zero exit status 1.
[2025-02-25T16:58:18.378+0000] {taskinstance.py:1400} INFO - Marking task as FAILED. dag_id=coingecko_mapreduce_dag, task_id=run_mapreduce_job, execution_date=20250225T165251, start_date=20250225T165807, end_date=20250225T165818
[2025-02-25T16:58:18.408+0000] {standard_task_runner.py:104} ERROR - Failed to execute job 203 for task run_mapreduce_job (Command '['docker', 'exec', 'namenode', 'hadoop', 'jar', '/opt/hadoop-3.2.1/share/hadoop/tools/lib/hadoop-streaming-3.2.1.jar', '-input', '/user/etudiant/crypto/raw/YYYY=2025/MM=02/DD=25/coingecko_raw.json', '-output', '/user/etudiant/crypto/output/YYYY=2025/MM=02/DD=25', '-mapper', 'python3 mapper.py', '-reducer', 'python3 reducer.py', '-file', '/user/etudiant/crypto/scripts/mapper.py', '-file', '/user/etudiant/crypto/scripts/reducer.py']' returned non-zero exit status 1.; 512)
[2025-02-25T16:58:18.439+0000] {local_task_job_runner.py:228} INFO - Task exited with return code 1
[2025-02-25T16:58:18.498+0000] {taskinstance.py:2784} INFO - 0 downstream tasks scheduled from follow-on schedule check
