[2025-02-26T20:10:52.896+0000] {taskinstance.py:1159} INFO - Dependencies all met for dep_context=non-requeueable deps ti=<TaskInstance: yfinance_ingestion_dag.store_raw_data_in_hdfs manual__2025-02-26T20:10:39.616487+00:00 [queued]>
[2025-02-26T20:10:52.985+0000] {taskinstance.py:1159} INFO - Dependencies all met for dep_context=requeueable deps ti=<TaskInstance: yfinance_ingestion_dag.store_raw_data_in_hdfs manual__2025-02-26T20:10:39.616487+00:00 [queued]>
[2025-02-26T20:10:52.990+0000] {taskinstance.py:1361} INFO - Starting attempt 1 of 2
[2025-02-26T20:10:53.722+0000] {taskinstance.py:1382} INFO - Executing <Task(PythonOperator): store_raw_data_in_hdfs> on 2025-02-26 20:10:39.616487+00:00
[2025-02-26T20:10:53.751+0000] {standard_task_runner.py:57} INFO - Started process 519 to run task
[2025-02-26T20:10:53.774+0000] {standard_task_runner.py:84} INFO - Running: ['***', 'tasks', 'run', 'yfinance_ingestion_dag', 'store_raw_data_in_hdfs', 'manual__2025-02-26T20:10:39.616487+00:00', '--job-id', '52', '--raw', '--subdir', 'DAGS_FOLDER/pipeline.py', '--cfg-path', '/tmp/tmpvdr1x0o6']
[2025-02-26T20:10:53.785+0000] {standard_task_runner.py:85} INFO - Job 52: Subtask store_raw_data_in_hdfs
[2025-02-26T20:10:54.134+0000] {task_command.py:415} INFO - Running <TaskInstance: yfinance_ingestion_dag.store_raw_data_in_hdfs manual__2025-02-26T20:10:39.616487+00:00 [running]> on host e304e68c626e
[2025-02-26T20:10:54.563+0000] {taskinstance.py:1660} INFO - Exporting env vars: AIRFLOW_CTX_DAG_OWNER='etudiant' AIRFLOW_CTX_DAG_ID='yfinance_ingestion_dag' AIRFLOW_CTX_TASK_ID='store_raw_data_in_hdfs' AIRFLOW_CTX_EXECUTION_DATE='2025-02-26T20:10:39.616487+00:00' AIRFLOW_CTX_TRY_NUMBER='1' AIRFLOW_CTX_DAG_RUN_ID='manual__2025-02-26T20:10:39.616487+00:00'
[2025-02-26T20:10:54.640+0000] {taskinstance.py:1943} ERROR - Task failed with exception
Traceback (most recent call last):
  File "/home/airflow/.local/lib/python3.8/site-packages/airflow/operators/python.py", line 192, in execute
    return_value = self.execute_callable()
  File "/home/airflow/.local/lib/python3.8/site-packages/airflow/operators/python.py", line 209, in execute_callable
    return self.python_callable(*self.op_args, **self.op_kwargs)
  File "/opt/airflow/dags/pipeline.py", line 84, in store_raw_data_in_hdfs
    with open(local_file, 'w') as f:
PermissionError: [Errno 13] Permission denied: '/mnt/hadoop_data/yfinance_raw.json'
[2025-02-26T20:10:54.704+0000] {taskinstance.py:1400} INFO - Marking task as UP_FOR_RETRY. dag_id=yfinance_ingestion_dag, task_id=store_raw_data_in_hdfs, execution_date=20250226T201039, start_date=20250226T201052, end_date=20250226T201054
[2025-02-26T20:10:54.757+0000] {standard_task_runner.py:104} ERROR - Failed to execute job 52 for task store_raw_data_in_hdfs ([Errno 13] Permission denied: '/mnt/hadoop_data/yfinance_raw.json'; 519)
[2025-02-26T20:10:54.819+0000] {local_task_job_runner.py:228} INFO - Task exited with return code 1
[2025-02-26T20:10:54.888+0000] {taskinstance.py:2784} INFO - 0 downstream tasks scheduled from follow-on schedule check
