[2025-02-22T17:16:46.145+0000] {taskinstance.py:1159} INFO - Dependencies all met for dep_context=non-requeueable deps ti=<TaskInstance: test_docker_exec_hadoop.create_test_file_in_container manual__2025-02-22T17:16:41.833852+00:00 [queued]>
[2025-02-22T17:16:46.159+0000] {taskinstance.py:1159} INFO - Dependencies all met for dep_context=requeueable deps ti=<TaskInstance: test_docker_exec_hadoop.create_test_file_in_container manual__2025-02-22T17:16:41.833852+00:00 [queued]>
[2025-02-22T17:16:46.160+0000] {taskinstance.py:1361} INFO - Starting attempt 1 of 1
[2025-02-22T17:16:46.350+0000] {taskinstance.py:1382} INFO - Executing <Task(BashOperator): create_test_file_in_container> on 2025-02-22 17:16:41.833852+00:00
[2025-02-22T17:16:46.361+0000] {standard_task_runner.py:57} INFO - Started process 398 to run task
[2025-02-22T17:16:46.365+0000] {standard_task_runner.py:84} INFO - Running: ['***', 'tasks', 'run', 'test_docker_exec_hadoop', 'create_test_file_in_container', 'manual__2025-02-22T17:16:41.833852+00:00', '--job-id', '139', '--raw', '--subdir', 'DAGS_FOLDER/pipeline.py', '--cfg-path', '/tmp/tmpdung9nu4']
[2025-02-22T17:16:46.368+0000] {standard_task_runner.py:85} INFO - Job 139: Subtask create_test_file_in_container
[2025-02-22T17:16:46.452+0000] {task_command.py:415} INFO - Running <TaskInstance: test_docker_exec_hadoop.create_test_file_in_container manual__2025-02-22T17:16:41.833852+00:00 [running]> on host 5fdfec269bbd
[2025-02-22T17:16:46.557+0000] {taskinstance.py:1660} INFO - Exporting env vars: AIRFLOW_CTX_DAG_OWNER='***' AIRFLOW_CTX_DAG_ID='test_docker_exec_hadoop' AIRFLOW_CTX_TASK_ID='create_test_file_in_container' AIRFLOW_CTX_EXECUTION_DATE='2025-02-22T17:16:41.833852+00:00' AIRFLOW_CTX_TRY_NUMBER='1' AIRFLOW_CTX_DAG_RUN_ID='manual__2025-02-22T17:16:41.833852+00:00'
[2025-02-22T17:16:46.559+0000] {subprocess.py:63} INFO - Tmp dir root location: /tmp
[2025-02-22T17:16:46.561+0000] {subprocess.py:75} INFO - Running command: ['/bin/bash', '-c', 'docker exec -i hadoop-datanode bash -c "echo \'Ceci est un fichier de test pour vérifier l\'écriture depuis Airflow.\' > /mnt/hadoop_data/test_file.txt"']
[2025-02-22T17:16:46.573+0000] {subprocess.py:86} INFO - Output:
[2025-02-22T17:16:46.664+0000] {subprocess.py:93} INFO - bash: -c: line 0: unexpected EOF while looking for matching `''
[2025-02-22T17:16:46.667+0000] {subprocess.py:93} INFO - bash: -c: line 1: syntax error: unexpected end of file
[2025-02-22T17:16:46.677+0000] {subprocess.py:97} INFO - Command exited with return code 1
[2025-02-22T17:16:46.693+0000] {taskinstance.py:1943} ERROR - Task failed with exception
Traceback (most recent call last):
  File "/home/airflow/.local/lib/python3.8/site-packages/airflow/operators/bash.py", line 210, in execute
    raise AirflowException(
airflow.exceptions.AirflowException: Bash command failed. The command returned a non-zero exit code 1.
[2025-02-22T17:16:46.698+0000] {taskinstance.py:1400} INFO - Marking task as FAILED. dag_id=test_docker_exec_hadoop, task_id=create_test_file_in_container, execution_date=20250222T171641, start_date=20250222T171646, end_date=20250222T171646
[2025-02-22T17:16:46.719+0000] {standard_task_runner.py:104} ERROR - Failed to execute job 139 for task create_test_file_in_container (Bash command failed. The command returned a non-zero exit code 1.; 398)
[2025-02-22T17:16:46.740+0000] {local_task_job_runner.py:228} INFO - Task exited with return code 1
[2025-02-22T17:16:46.767+0000] {taskinstance.py:2784} INFO - 0 downstream tasks scheduled from follow-on schedule check
