[2025-02-26T20:47:00.314+0000] {taskinstance.py:1159} INFO - Dependencies all met for dep_context=non-requeueable deps ti=<TaskInstance: yfinance_ingestion_dag.run_mapreduce scheduled__2025-01-17T00:00:00+00:00 [queued]>
[2025-02-26T20:47:00.367+0000] {taskinstance.py:1159} INFO - Dependencies all met for dep_context=requeueable deps ti=<TaskInstance: yfinance_ingestion_dag.run_mapreduce scheduled__2025-01-17T00:00:00+00:00 [queued]>
[2025-02-26T20:47:00.376+0000] {taskinstance.py:1361} INFO - Starting attempt 2 of 2
[2025-02-26T20:47:00.429+0000] {taskinstance.py:1382} INFO - Executing <Task(BashOperator): run_mapreduce> on 2025-01-17 00:00:00+00:00
[2025-02-26T20:47:00.445+0000] {standard_task_runner.py:57} INFO - Started process 3117 to run task
[2025-02-26T20:47:00.448+0000] {standard_task_runner.py:84} INFO - Running: ['***', 'tasks', 'run', 'yfinance_ingestion_dag', 'run_mapreduce', 'scheduled__2025-01-17T00:00:00+00:00', '--job-id', '427', '--raw', '--subdir', 'DAGS_FOLDER/pipeline.py', '--cfg-path', '/tmp/tmpmy5ktu3r']
[2025-02-26T20:47:00.469+0000] {standard_task_runner.py:85} INFO - Job 427: Subtask run_mapreduce
[2025-02-26T20:47:00.652+0000] {task_command.py:415} INFO - Running <TaskInstance: yfinance_ingestion_dag.run_mapreduce scheduled__2025-01-17T00:00:00+00:00 [running]> on host 3c0faf52b292
[2025-02-26T20:47:01.101+0000] {taskinstance.py:1660} INFO - Exporting env vars: AIRFLOW_CTX_DAG_OWNER='etudiant' AIRFLOW_CTX_DAG_ID='yfinance_ingestion_dag' AIRFLOW_CTX_TASK_ID='run_mapreduce' AIRFLOW_CTX_EXECUTION_DATE='2025-01-17T00:00:00+00:00' AIRFLOW_CTX_TRY_NUMBER='2' AIRFLOW_CTX_DAG_RUN_ID='scheduled__2025-01-17T00:00:00+00:00'
[2025-02-26T20:47:01.106+0000] {subprocess.py:63} INFO - Tmp dir root location: /tmp
[2025-02-26T20:47:01.111+0000] {subprocess.py:75} INFO - Running command: ['/bin/bash', '-c', '\n        docker exec -i -u root namenode bash -c \'         cd /tmp &&         cp /mnt/hadoop_data/mapreduce/mapper.py . &&         cp /mnt/hadoop_data/mapreduce/reducer.py . &&         chmod +x mapper.py reducer.py &&         hdfs dfs -rm -r hdfs:///user/etudiant/crypto/processed/YYYY=2025/MM=01/DD=17 || true &&         hadoop jar /opt/hadoop-3.2.1/share/hadoop/tools/lib/hadoop-streaming-3.2.1.jar         -files mapper.py,reducer.py         -mapper "python mapper.py"         -reducer "python reducer.py"         -input hdfs:///user/etudiant/crypto/raw/YYYY=2025/MM=01/DD=17/yfinance_raw.json         -output hdfs:///user/etudiant/crypto/processed/YYYY=2025/MM=01/DD=17\'\n        ']
[2025-02-26T20:47:01.157+0000] {subprocess.py:86} INFO - Output:
[2025-02-26T20:47:15.664+0000] {subprocess.py:93} INFO - rm: `hdfs:///user/etudiant/crypto/processed/YYYY=2025/MM=01/DD=17': No such file or directory
[2025-02-26T20:47:26.771+0000] {subprocess.py:93} INFO - 2025-02-26 20:47:26,767 INFO impl.MetricsConfig: Loaded properties from hadoop-metrics2.properties
[2025-02-26T20:47:27.059+0000] {subprocess.py:93} INFO - 2025-02-26 20:47:27,057 INFO impl.MetricsSystemImpl: Scheduled Metric snapshot period at 10 second(s).
[2025-02-26T20:47:27.061+0000] {subprocess.py:93} INFO - 2025-02-26 20:47:27,057 INFO impl.MetricsSystemImpl: JobTracker metrics system started
[2025-02-26T20:47:27.120+0000] {subprocess.py:93} INFO - 2025-02-26 20:47:27,117 WARN impl.MetricsSystemImpl: JobTracker metrics system already initialized!
[2025-02-26T20:47:28.356+0000] {subprocess.py:93} INFO - 2025-02-26 20:47:28,345 INFO mapreduce.JobSubmitter: Cleaning up the staging area file:/tmp/hadoop/mapred/staging/root478685083/.staging/job_local478685083_0001
[2025-02-26T20:47:28.385+0000] {subprocess.py:93} INFO - 2025-02-26 20:47:28,350 ERROR streaming.StreamJob: Error Launching job : Input path does not exist: hdfs:/user/etudiant/crypto/raw/YYYY=2025/MM=01/DD=17/yfinance_raw.json
[2025-02-26T20:47:28.399+0000] {subprocess.py:93} INFO - Streaming Command Failed!
[2025-02-26T20:47:29.208+0000] {subprocess.py:97} INFO - Command exited with return code 5
[2025-02-26T20:47:29.247+0000] {taskinstance.py:1943} ERROR - Task failed with exception
Traceback (most recent call last):
  File "/home/airflow/.local/lib/python3.8/site-packages/airflow/operators/bash.py", line 210, in execute
    raise AirflowException(
airflow.exceptions.AirflowException: Bash command failed. The command returned a non-zero exit code 5.
[2025-02-26T20:47:29.263+0000] {taskinstance.py:1400} INFO - Marking task as FAILED. dag_id=yfinance_ingestion_dag, task_id=run_mapreduce, execution_date=20250117T000000, start_date=20250226T204700, end_date=20250226T204729
[2025-02-26T20:47:29.321+0000] {standard_task_runner.py:104} ERROR - Failed to execute job 427 for task run_mapreduce (Bash command failed. The command returned a non-zero exit code 5.; 3117)
[2025-02-26T20:47:29.401+0000] {local_task_job_runner.py:228} INFO - Task exited with return code 1
[2025-02-26T20:47:29.448+0000] {taskinstance.py:2784} INFO - 0 downstream tasks scheduled from follow-on schedule check
