[2025-02-22T16:08:56.879+0000] {taskinstance.py:1159} INFO - Dependencies all met for dep_context=non-requeueable deps ti=<TaskInstance: test_volume_shared_dag.write_test_file manual__2025-02-22T16:08:49.073557+00:00 [queued]>
[2025-02-22T16:08:56.889+0000] {taskinstance.py:1159} INFO - Dependencies all met for dep_context=requeueable deps ti=<TaskInstance: test_volume_shared_dag.write_test_file manual__2025-02-22T16:08:49.073557+00:00 [queued]>
[2025-02-22T16:08:56.889+0000] {taskinstance.py:1361} INFO - Starting attempt 1 of 1
[2025-02-22T16:08:57.001+0000] {taskinstance.py:1382} INFO - Executing <Task(PythonOperator): write_test_file> on 2025-02-22 16:08:49.073557+00:00
[2025-02-22T16:08:57.008+0000] {standard_task_runner.py:57} INFO - Started process 63 to run task
[2025-02-22T16:08:57.013+0000] {standard_task_runner.py:84} INFO - Running: ['***', 'tasks', 'run', 'test_volume_shared_dag', 'write_test_file', 'manual__2025-02-22T16:08:49.073557+00:00', '--job-id', '127', '--raw', '--subdir', 'DAGS_FOLDER/pipeline.py', '--cfg-path', '/tmp/tmpmahxqd6y']
[2025-02-22T16:08:57.016+0000] {standard_task_runner.py:85} INFO - Job 127: Subtask write_test_file
[2025-02-22T16:08:57.118+0000] {task_command.py:415} INFO - Running <TaskInstance: test_volume_shared_dag.write_test_file manual__2025-02-22T16:08:49.073557+00:00 [running]> on host 5fdfec269bbd
[2025-02-22T16:08:57.262+0000] {taskinstance.py:1660} INFO - Exporting env vars: AIRFLOW_CTX_DAG_OWNER='***' AIRFLOW_CTX_DAG_ID='test_volume_shared_dag' AIRFLOW_CTX_TASK_ID='write_test_file' AIRFLOW_CTX_EXECUTION_DATE='2025-02-22T16:08:49.073557+00:00' AIRFLOW_CTX_TRY_NUMBER='1' AIRFLOW_CTX_DAG_RUN_ID='manual__2025-02-22T16:08:49.073557+00:00'
[2025-02-22T16:08:57.265+0000] {taskinstance.py:1943} ERROR - Task failed with exception
Traceback (most recent call last):
  File "/home/airflow/.local/lib/python3.8/site-packages/airflow/operators/python.py", line 192, in execute
    return_value = self.execute_callable()
  File "/home/airflow/.local/lib/python3.8/site-packages/airflow/operators/python.py", line 209, in execute_callable
    return self.python_callable(*self.op_args, **self.op_kwargs)
  File "/opt/airflow/dags/pipeline.py", line 16, in write_test_file
    with open(test_file_path, "w") as f:
PermissionError: [Errno 13] Permission denied: '/mnt/hadoop_data/test_file.txt'
[2025-02-22T16:08:57.278+0000] {taskinstance.py:1400} INFO - Marking task as FAILED. dag_id=test_volume_shared_dag, task_id=write_test_file, execution_date=20250222T160849, start_date=20250222T160856, end_date=20250222T160857
[2025-02-22T16:08:57.295+0000] {standard_task_runner.py:104} ERROR - Failed to execute job 127 for task write_test_file ([Errno 13] Permission denied: '/mnt/hadoop_data/test_file.txt'; 63)
[2025-02-22T16:08:57.306+0000] {local_task_job_runner.py:228} INFO - Task exited with return code 1
[2025-02-22T16:08:57.341+0000] {taskinstance.py:2784} INFO - 0 downstream tasks scheduled from follow-on schedule check
