[2025-02-24T16:22:47.724+0000] {taskinstance.py:1159} INFO - Dependencies all met for dep_context=non-requeueable deps ti=<TaskInstance: coingecko_mapreduce_dag.run_mapreduce_job scheduled__2025-02-23T00:00:00+00:00 [queued]>
[2025-02-24T16:22:47.738+0000] {taskinstance.py:1159} INFO - Dependencies all met for dep_context=requeueable deps ti=<TaskInstance: coingecko_mapreduce_dag.run_mapreduce_job scheduled__2025-02-23T00:00:00+00:00 [queued]>
[2025-02-24T16:22:47.739+0000] {taskinstance.py:1361} INFO - Starting attempt 2 of 2
[2025-02-24T16:22:47.768+0000] {taskinstance.py:1382} INFO - Executing <Task(BashOperator): run_mapreduce_job> on 2025-02-23 00:00:00+00:00
[2025-02-24T16:22:47.777+0000] {standard_task_runner.py:57} INFO - Started process 3117 to run task
[2025-02-24T16:22:47.785+0000] {standard_task_runner.py:84} INFO - Running: ['***', 'tasks', 'run', 'coingecko_mapreduce_dag', 'run_mapreduce_job', 'scheduled__2025-02-23T00:00:00+00:00', '--job-id', '22', '--raw', '--subdir', 'DAGS_FOLDER/test_hello.py', '--cfg-path', '/tmp/tmpztx4cc51']
[2025-02-24T16:22:47.795+0000] {standard_task_runner.py:85} INFO - Job 22: Subtask run_mapreduce_job
[2025-02-24T16:22:47.928+0000] {task_command.py:415} INFO - Running <TaskInstance: coingecko_mapreduce_dag.run_mapreduce_job scheduled__2025-02-23T00:00:00+00:00 [running]> on host 94f70d9be3b1
[2025-02-24T16:22:48.292+0000] {taskinstance.py:1660} INFO - Exporting env vars: AIRFLOW_CTX_DAG_OWNER='etudiant' AIRFLOW_CTX_DAG_ID='coingecko_mapreduce_dag' AIRFLOW_CTX_TASK_ID='run_mapreduce_job' AIRFLOW_CTX_EXECUTION_DATE='2025-02-23T00:00:00+00:00' AIRFLOW_CTX_TRY_NUMBER='2' AIRFLOW_CTX_DAG_RUN_ID='scheduled__2025-02-23T00:00:00+00:00'
[2025-02-24T16:22:48.302+0000] {subprocess.py:63} INFO - Tmp dir root location: /tmp
[2025-02-24T16:22:48.305+0000] {subprocess.py:75} INFO - Running command: ['/bin/bash', '-c', '\n        docker exec -i -u root namenode bash -c "\n            hdfs dfs -rm -r /user/etudiant/crypto/processed/YYYY=2025/MM=02/DD=23 || true &&             hadoop jar /opt/hadoop-3.2.1/share/hadoop/tools/lib/hadoop-streaming-3.2.1.jar                 -files hdfs:///user/etudiant/scripts/mapper.py,hdfs:///user/etudiant/scripts/reducer.py                 -mapper \'python3 mapper.py\'                 -reducer \'python3 reducer.py\'                 -input /user/etudiant/crypto/raw/YYYY=2025/MM=02/DD=23/coingecko_raw.json                 -output /user/etudiant/crypto/processed/YYYY=2025/MM=02/DD=23\n        "\n        ']
[2025-02-24T16:22:48.337+0000] {subprocess.py:86} INFO - Output:
[2025-02-24T16:22:53.244+0000] {subprocess.py:93} INFO - rm: `/user/etudiant/crypto/processed/YYYY=2025/MM=02/DD=23': No such file or directory
[2025-02-24T16:22:58.508+0000] {subprocess.py:93} INFO - 2025-02-24 16:22:58,503 INFO impl.MetricsConfig: Loaded properties from hadoop-metrics2.properties
[2025-02-24T16:22:58.743+0000] {subprocess.py:93} INFO - 2025-02-24 16:22:58,741 INFO impl.MetricsSystemImpl: Scheduled Metric snapshot period at 10 second(s).
[2025-02-24T16:22:58.744+0000] {subprocess.py:93} INFO - 2025-02-24 16:22:58,741 INFO impl.MetricsSystemImpl: JobTracker metrics system started
[2025-02-24T16:22:58.761+0000] {subprocess.py:93} INFO - 2025-02-24 16:22:58,760 WARN impl.MetricsSystemImpl: JobTracker metrics system already initialized!
[2025-02-24T16:22:59.055+0000] {subprocess.py:93} INFO - 2025-02-24 16:22:59,054 INFO sasl.SaslDataTransferClient: SASL encryption trust check: localHostTrusted = false, remoteHostTrusted = false
[2025-02-24T16:22:59.199+0000] {subprocess.py:93} INFO - 2025-02-24 16:22:59,196 INFO mapreduce.JobSubmitter: Cleaning up the staging area file:/tmp/hadoop/mapred/staging/root2087160807/.staging/job_local2087160807_0001
[2025-02-24T16:22:59.201+0000] {subprocess.py:93} INFO - 2025-02-24 16:22:59,198 ERROR streaming.StreamJob: Error launching job , bad input path : File does not exist: /tmp/hadoop/mapred/staging/root2087160807/.staging/job_local2087160807_0001/files/mapper.py
[2025-02-24T16:22:59.202+0000] {subprocess.py:93} INFO - Streaming Command Failed!
[2025-02-24T16:22:59.680+0000] {subprocess.py:97} INFO - Command exited with return code 2
[2025-02-24T16:22:59.706+0000] {taskinstance.py:1943} ERROR - Task failed with exception
Traceback (most recent call last):
  File "/home/airflow/.local/lib/python3.8/site-packages/airflow/operators/bash.py", line 210, in execute
    raise AirflowException(
airflow.exceptions.AirflowException: Bash command failed. The command returned a non-zero exit code 2.
[2025-02-24T16:22:59.713+0000] {taskinstance.py:1400} INFO - Marking task as FAILED. dag_id=coingecko_mapreduce_dag, task_id=run_mapreduce_job, execution_date=20250223T000000, start_date=20250224T162247, end_date=20250224T162259
[2025-02-24T16:22:59.736+0000] {standard_task_runner.py:104} ERROR - Failed to execute job 22 for task run_mapreduce_job (Bash command failed. The command returned a non-zero exit code 2.; 3117)
[2025-02-24T16:22:59.781+0000] {local_task_job_runner.py:228} INFO - Task exited with return code 1
[2025-02-24T16:22:59.804+0000] {taskinstance.py:2784} INFO - 0 downstream tasks scheduled from follow-on schedule check
